Workbook

Sheet Saldos Iniciales
A1: Empresa | B1: Cuenta Bancaria | C1: Mes/Año inicio | D1: Saldo Inicial
A2: CFT Group | B2: Bank of America - CFT Group - 4415-USD | C2: 2026-07 | D2: 132689.05 | E2: 2026-05
A3: CFT Group | B3: Amerant Bank - CFT Group - 1906-USD | C3: 2026-07 | D3: 62799.53 | E3: 2026-05
A4: CFT Group | B4: Northern Trust - CFT Group - 1355-USD | C4: 2026-07 | D4: 5274.85 | E4: 2026-05
A5: M1B | B5: Amerant Bank - M1B - 0906-USD | C5: 2026-07 | D5: 39539.54 | E5: 2026-05
A6: M1B | B6: Amerant Bank DACA - M1B - 8231-USD | C6: 2026-07 | D6: 5000 | E6: 2026-05
A7: Durand | B7: Amerant Bank - Durand - 0106-USD | C7: 2026-07 | D7: 1669.89 | E7: 2026-05
A8: A&M Imports | B8: Bank of America - A&M Imports - 3797-USD | C8: 2026-07 | D8: 177088.59 | E8: 2026-05
A9: SSP Capital | B9: Bank of America - SSP Capital - 2580-USD | C9: 2026-07 | D9: 12379.18 | E9: 2026-05
A10: SSP Capital | B10: Bank of America - SSP Capital - 1655-USD | C10: 2026-07 | D10: 759.07 | E10: 2026-05
A11: SSP Capital | B11: EFG - SSP Capital - 21.0-USD | C11: 2026-07 | E11: 2026-05
A12: SSP Capital | B12: Amerant Bank - SSP Capital - 4706-USD | C12: 2026-07 | D12: 219857.82 | E12: 2026-05
A13: SSP Capital | B13: Northern Trust - SSP Capital - 1452-USD | C13: 2026-07 | D13: 4870.11 | E13: 2026-05
A14: SSP Capital | B14: Amerant Bank Money Market - SSP Capital - 1006-USD | C14: 2026-07 | D14: 747521.2 | E14: 2026-05
A15: SSP Capital | B15: Amerant Bank DACA - SSP Capital - 9873-USD | C15: 2026-07 | D15: 5000 | E15: 2026-05
A16: Cross Family Trust | B16: Ocean Bank - Cross Family Trust - 3405-USD | C16: 2026-07 | D16: 57206.89 | E16: 2026-05
A17: Cross Family Trust | B17: Northern Trust - Cross Family Trust - 9263-USD | C17: 2026-07 | D17: 6365 | E17: 2026-05
A18: Cross Family Trust | B18: Bank of America - Cross Family Trust - 3124-USD | C18: 2026-07 | D18: 13221.89 | E18: 2026-05
A19: Cross Family Trust | B19: Amerant Bank - Cross Family Trust - 4706-USD | C19: 2026-07 | D19: 65717.6 | E19: 2026-05
A20: Cross Security Trust | B20: Bank of America - Cross Security Trust - 6642-USD | C20: 2026-07 | D20: 13088.59 | E20: 2026-05
A21: Electrama | B21: Chase Bank - Electrama - 6520-USD | C21: 2026-07 | D21: 92.02 | E21: 2026-06
A22: Sacred Valley Capital | B22: Bank of America - Sacred Valley Capital - 4376-USD | C22: 2026-07 | D22: 144.25 | E22: 2026-05
A23: YWC Capital | B23: Bank of America - YWC Capital - 0282-USD | C23: 2026-07 | D23: 2297.67 | E23: 2026-05
... A35: Go Blue | B35: Amerant Bank - Go Blue - 1557-USD | C35: 2026-07 | D35: 5293.35 | E35: 2026-07
A36: Pacha Ventures LLC | B36: Amerant Bank - Pacha Ventures LLC - 0206-USD | C36: 2026-09 | D36: 301167.45
A37: CFT1 Residence | B37: Amerant Bank - CFT 1 residence LLC - 0573-USD | C37: 2026-09 | D37: 1855.87
A38: CFT1 Residence | B38: Amerant Bank - CFT 1 residence LLC - 6607-USD | C38: 2026-09 | D38: 49579.06
A39: Carmen Cross Irrevocable Trust | B39: Amerant Bank - Carmen Cross Irrevocable Trust - 3406-USD | C39: 2026-09 | D39: 3631.96
A40: SIYP LLC | B40: Amerant Bank - SIYP LLC - 7820-USD | C40: 2026-09 | D40: 2301.3
A41: Prendamas SRL | B41: Amerant Bank - Prendamas SRL - 8160-USD | C41: 2026-09 | D41: 92394.88
A42: 360 Harbor Lane LLC | B42: Amerant Bank - 360 Harbor Lane LLC - 9306-USD | C42: 2026-09 | D42: 794.01
A43: Five Capital | B43: Bank of America - Five Capital - 3094-USD | C43: 2026-09 | D43: 5445.57
A44: SIYP LLC | B44: Bank of America - SIYP LLC - 2179-USD | C44: 2026-09 | D44: 18.13
A45: Nobe Aparments | B45: Bank of America - Nobe Aparments - 2113-USD | C45: 2026-09 | D45: 206959.21
A46: Nobe Aparments | B46: Bank of America - Nobe Aparments - 8047-USD | C46: 2026-09 | D46: 31093.71
A47: Don Cross Life | B47: Bank of America - Don Cross Life Trust - 9372-USD | C47: 2026-09 | D47: 303874.72

Sheet Listas
A1: Empresas | B1: Cuentas Bancarias | C1: Banco | D1: Tipos | E1: Concepto | F1: Categoria | G1: Ext/Int
A2: CFT Group | B2: Bank of America - CFT Group - 4415-USD | C2: Bank of America | D2: Ingreso | E2: Eg.Gastos Operativos (Proveedor) | F2: Operativo | G2: Externo
A3: CFT Group | B3: Amerant Bank - CFT Group - 1906-USD | C3: Amerant Bank | D3: Egreso | E3: Eg.Gastos Operativos (Tarjeta credito) | F3: Operativo | G3: Externo
A4: CFT Group | B4: Northern Trust - CFT Group - 1355-USD | C4: Northern Trust | E4: Eg.Gastos Personal (Nomina, bono, etc) | F4: Operativo | G4: Externo
A5: M1B | B5: Amerant Bank - M1B - 0906-USD | C5: Amerant Bank | E5: Eg.Gastos Personal (Seguro Medico) | F5: Operativo | G5: Externo
A6: M1B | B6: Amerant Bank DACA - M1B - 8231-USD | C6: Amerant Bank DACA | E6: Eg.Gastos Personal (Taxes) | F6: Operativo | G6: Externo
A7: Durand | B7: Amerant Bank - Durand - 0106-USD | C7: Amerant Bank | E7: Eg.Gastos Personal (Trustee) | F7: Operativo | G7: Externo
A8: A&M Imports | B8: Bank of America - A&M Imports - 3797-USD | C8: Bank of America | E8: Eg.Gastos Bancarios | F8: Operativo | G8: Externo
A9: SSP Capital | B9: Bank of America - SSP Capital - 2580-USD | C9: Bank of America | E9: Eg.Impuestos | F9: Operativo | G9: Externo
A10: SSP Capital | B10: Bank of America - SSP Capital - 1655-USD | C10: Bank of America | E10: Eg.Deuda Terceros (Intereses) | F10: Financiamiento | G10: Externo
A11: SSP Capital | B11: EFG - SSP Capital - 21.0-USD | C11: EFG | E11: Eg.Deuda Terceros (Capital) | F11: Financiamiento | G11: Externo
A12: SSP Capital | B12: Amerant Bank - SSP Capital - 4706-USD | C12: Amerant Bank | E12: Eg.Deuda Terceros (Intereses+Capital) | F12: Financiamiento | G12: Externo
A13: SSP Capital | B13: Northern Trust - SSP Capital - 1452-USD | C13: Northern Trust | E13: Eg.Deuda Relacionadas (Intereses) | F13: Financiamiento | G13: Externo
A14: SSP Capital | B14: Amerant Bank Money Market - SSP Capital - 1006-USD | C14: Amerant Bank Money Market | E14: Eg.Deuda Relacionadas (Capital) | F14: Financiamiento | G14: Externo
A15: SSP Capital | B15: Amerant Bank DACA - SSP Capital - 9873-USD | C15: Amerant Bank DACA | E15: Eg.Deuda Relacionadas (Intereses+Capital) | F15: Financiamiento | G15: Externo
... A29: 2515 Overbrook | B29: Bank of America - 2515 Overbrook - 4648-USD | C29: Bank of America | E29: Eg.Otros egresos operativos | F29: Operativo | G29: Externo
A30: 2515 Overbrook | B30: Bank of America - 2515 Overbrook - 9923-USD | C30: Bank of America
A31: 112 Florida Ave | B31: Bank of America - 112 Florida Ave - 3259-USD | C31: Bank of America | E31: Ing.Dividendos Recibidos de Unidades de Negocio | F31: Inversion | G31: Externo
A32: 3628 Thomas Ave | B32: Bank of America - 3628 Thomas Ave - 4406-USD | C32: Bank of America | E32: Ing.Dividendos Recibidos de Empresas Relacionadas | F32: Inversion | G32: Interno
A33: Green Harbor Trust | B33: Amerant Bank - Green Harbor Trust - 7253-USD | C33: Amerant Bank | E33: Ing.Intereses Recibidos de Unidad de Negocio | F33: Operativo | G33: Externo
A34: Go Blue | B34: Amerant Bank - Go Blue - 8206-USD | C34: Amerant Bank | E34: Ing.Intereses Recibidos de Empresas Relacionadas | F34: Operativo | G34: Interno
A35: EC AUTO LLC (no existe) | B35: Amerant Bank - EC AUTO LLC (no existe) - 0509-USD | C35: Amerant Bank | E35: Ing.Capital Recibido de Unidad de Negocio | F35: Operativo | G35: Externo
A36: Go Blue | B36: Amerant Bank - Go Blue - 1557-USD | C36: Amerant Bank | E36: Ing.Capital Recibido de Empresas Relacionadas | F36: Operativo | G36: Interno
A37: Pacha Ventures LLC | B37: Amerant Bank - Pacha Ventures LLC - 0206-USD | C37: Amerant Bank | E37: Ing.Interes+Capital Recibido de Unidad de Negocio | F37: Operativo | G37: Externo
A38: CFT1 Residence | B38: Amerant Bank - CFT 1 residence LLC - 0573-USD | C38: Amerant Bank | E38: Ing.Interes+Capital Recibido de Empresas Relacionadas | F38: Operativo | G38: Interno
A39: CFT1 Residence | B39: Amerant Bank - CFT 1 residence LLC - 6607-USD | C39: Amerant Bank | E39: Ing.Deuda Recibida de Unidades de negocio | F39: Financiamiento | G39: Externo
A40: Carmen Cross Irrevocable Trust | B40: Amerant Bank - Carmen Cross Irrevocable Trust - 3406-USD | C40: Amerant Bank | E40: Ing.Deuda Recibida de Empresas relacionadas | F40: Financiamiento | G40: Interno
A41: SIYP LLC | B41: Amerant Bank - SIYP LLC - 7820-USD | C41: Amerant Bank | E41: Ing.Deuda Recibida de Terceros | F41: Financiamiento | G41: Externo
A42: Prendamas SRL | B42: Amerant Bank - Prendamas SRL - 8160-USD | C42: Amerant Bank | E42: Ing.Recibe Aporte de Capital de Empresas relacionadas | F42: Inversion | G42: Interno
... A48: Don Cross Life | B48: Bank of America - Don Cross Life Trust - 9372-USD | C48: Bank of America | E48: Ing.Devolucion de Aporte de Capital | F48: Inversion | G48: Interno
E49: Ing.Interes bancario | F49: Operativo | G49: Externo
E50: Ing.Transferencias entre cuentas (Misma entidad legal) | F50: Operativo | G50: Interno
E51: Ing.Otros Ingresos Inversion | F51: Inversion | G51: Externo
E52: Ing.Otros Ingresos Operativos | F52: Operativo | G52: Externo

Sheet Cuentas
A1: Grupo | B1: Subsidiaria | C1: Cuenta bancaria
A2: SSP Group | C2: Bank of America - CFT Group - 4415-USD
A3: SSP Group | C3: Amerant Bank - CFT Group - 1906-USD
A4: SSP Group | C4: Northern Trust - CFT Group - 1355-USD
A5: SSP Group | C5: Amerant Bank - M1B - 0906-USD
A6: SSP Group | C6: Amerant Bank DACA - M1B - 8231-USD
A7: SSP Group | C7: Amerant Bank - Durand - 0106-USD
A8: SSP Group | C8: Bank of America - A&M Imports - 3797-USD
A9: SSP Group | C9: Bank of America - SSP Capital - 2580-USD
A10: SSP Group | C10: Bank of America - SSP Capital - 1655-USD
A11: SSP Group | C11: Amerant Bank - SSP Capital - 4706-USD
A12: SSP Group | C12: Northern Trust - SSP Capital - 1452-USD
A13: SSP Group | C13: Amerant Bank Money Market - SSP Capital - 1006-USD
... A44: Unidades de Negocio | C44: Amerant Bank - Prendamas SRL - 8160-USD
B45: Trust | C45: Bank of America - Cross Family Trust - 3124-USD
B46: Trust | C46: Northern Trust - Cross Family Trust - 9263-USD
B47: Trust | C47: Ocean Bank - Cross Family Trust - 3405-USD
B48: Trust | C48: Amerant Bank - Cross Family Trust - 4706-USD
B49: Trust | C49: Bank of America - Cross Security Trust - 6642-USD
B50: Trust | C50: Amerant Bank - Carmen Cross Irrevocable Trust - 3406-USD
B51: Trust | C51: Bank of America - Green Stone Trust - 3632-USD
B52: Trust | C52: Amerant Bank - Green Harbor Trust - 7253-USD
B53: Trust | C53: Bank of America - Don Cross Life Trust - 9372-USD

Sheet Movimientos
A1: ID | B1: Fecha | C1: Empresa | D1: Cuenta Bancaria | E1: Banco | F1: Tipo de Movimiento | G1: Categoria / Concepto | H1: Descripcion | I1: Ext/Int | J1: Monto (S/) | K1: Monto con signo | L1: Mes/Año | M1: Saldo del dia (acumulado) | N1: Ingreso | O1: Egreso | P1: Variación | Q1: Grupo | R1: Subsidiaria
B2: 46143 | C2: =_xlfn.XLOOKUP(tblMovimientos[[#This Row],[Cuenta Bancaria]],Listas!$B:$B,Listas!$A:$A,"") -> A&M Imports | D2: Bank of America - A&M Imports - 3797-USD | E2: =_xlfn.XLOOKUP(tblMovimientos[[#This Row],[Cuenta Bancaria]],Listas!$B:$B,Listas!$C:$C,"") -> Bank of America | F2: Ingreso | G2: Ing.Exportacion de oro de Unidad de Negocio | H2: =IFERROR(_xlfn.XLOOKUP(G2,Listas!E:E,Listas!F:F,""),"") -> Operativo | I2: Externo | J2: 400000 | K2: =IF(F2="Ingreso",J2,-J2) -> 400000 | L2: 2026-05 | M2: =SUMIFS('Saldos Iniciales'!$D:$D,'Saldos Iniciales'!$A:$A,C2,'Saldos Iniciales'!$B:$B,D2)+SUMIFS($K$1:$K$1324,$C$1:$C$1324,C2,$D$1:$D$1324,D2,$B$1:$B$1324,"<="&B2) -> 589990.3 | N2: =IF(tblMovimientos[[#This Row],[Tipo de Movimiento]]="Ingreso",tblMovimientos[[#This Row],[Monto (S/)]],"0") -> 400000 | O2: =IF(tblMovimientos[[#This Row],[Tipo de Movimiento]]="Egreso",tblMovimientos[[#This Row],[Monto (S/)]],"0") -> 0 | P2: =IF(tblMovimientos[[#This Row],[Tipo de Movimiento]]="Ingreso",tblMovimientos[[#This Row],[Ingreso]],-tblMovimientos[[#This Row],[Egreso]]) -> 400000 | Q2: =_xlfn.XLOOKUP(tblMovimientos[[#This Row],[Cuenta Bancaria]],Cuentas!$C:$C,Cuentas!$A:$A,"")&"" -> SSP Group | R2: =_xlfn.XLOOKUP(tblMovimientos[[#This Row],[Cuenta Bancaria]],Cuentas!$C:$C,Cuentas!$B:$B,"",0,-1)&""
B3: 46143 | C3: =_xlfn.XLOOKUP(tblMovimientos[[#This Row],[Cuenta Bancaria]],Listas!$B:$B,Listas!$A:$A,"") -> A&M Imports | D3: Bank of America - A&M Imports - 3797-USD | E3: =_xlfn.XLOOKUP(tblMovimientos[[#This Row],[Cuenta Bancaria]],Listas!$B:$B,Listas!$C:$C,"") -> Bank of America | F3: Ingreso | G3: Ing.Intereses Recibidos de Unidad de Negocio | H3: =IFERROR(_xlfn.XLOOKUP(G3,Listas!E:E,Listas!F:F,""),"") -> Operativo | I3: Externo | J3: 12901.71 | K3: =IF(F3="Ingreso",J3,-J3) -> 12901.71 | L3: 2026-05 | M3: =SUMIFS('Saldos Iniciales'!$D:$D,'Saldos Iniciales'!$A:$A,C3,'Saldos Iniciales'!$B:$B,D3)+SUMIFS($K$1:$K$1324,$C$1:$C$1324,C3,$D$1:$D$1324,D3,$B$1:$B$1324,"<="&B3) -> 589990.3 | N3: =IF(tblMovimientos[[#This Row],[Tipo de Movimiento]]="Ingreso",tblMovimientos[[#This Row],[Monto (S/)]],"0") -> 12901.71 | O3: =IF(tblMovimientos[[#This Row],[Tipo de Movimiento]]="Egreso",tblMovimientos[[#This Row],[Monto (S/)]],"0") -> 0 | P3: =IF(tblMovimientos[[#This Row],[Tipo de Movimiento]]="Ingreso",tblMovimientos[[#This Row],[Ingreso]],-tblMovimientos[[#This Row],[Egreso]]) -> 12901.71 | Q3: =_xlfn.XLOOKUP(tblMovimientos[[#This Row],[Cuenta Bancaria]],Cuentas!$C:$C,Cuentas!$A:$A,"")&"" -> SSP Group | R3: =_xlfn.XLOOKUP(tblMovimientos[[#This Row],[Cuenta Bancaria]],Cuentas!$C:$C,Cuentas!$B:$B,"",0,-1)&""
B4: 46143 | C4: =_xlfn.XLOOKUP(tblMovimientos[[#This Row],[Cuenta Bancaria]],Listas!$B:$B,Listas!$A:$A,"") -> Sacred Valley Capital | D4: Bank of America - Sacred Valley Capital - 4376-USD | E4: =_xlfn.XLOOKUP(tblMovimientos[[#This Row],[Cuenta Bancaria]],Listas!$B:$B,Listas!$C:$C,"") -> Bank of America | F4: Egreso | G4: Eg.Gastos Bancarios | H4: =IFERROR(_xlfn.XLOOKUP(G4,Listas!E:E,Listas!F:F,""),"") -> Operativo | I4: =IFERROR(_xlfn.XLOOKUP(G4,Listas!E:E,Listas!G:G,""),"") -> Externo | J4: 29.95 | K4: =IF(F4="Ingreso",J4,-J4) -> -29.95 | L4: 2026-05 | M4: =SUMIFS('Saldos Iniciales'!$D:$D,'Saldos Iniciales'!$A:$A,C4,'Saldos Iniciales'!$B:$B,D4)+SUMIFS($K$1:$K$1324,$C$1:$C$1324,C4,$D$1:$D$1324,D4,$B$1:$B$1324,"<="&B4) -> 114.3 | N4: =IF(tblMovimientos[[#This Row],[Tipo de Movimiento]]="Ingreso",tblMovimientos[[#This Row],[Monto (S/)]],"0") -> 0 | O4: =IF(tblMovimientos[[#This Row],[Tipo de Movimiento]]="Egreso",tblMovimientos[[#This Row],[Monto (S/)]],"0") -> 29.95 | P4: =IF(tblMovimientos[[#This Row],[Tipo de Movimiento]]="Ingreso",tblMovimientos[[#This Row],[Ingreso]],-tblMovimientos[[#This Row],[Egreso]]) -> -29.95 | Q4: =_xlfn.XLOOKUP(tblMovimientos[[#This Row],[Cuenta Bancaria]],Cuentas!$C:$C,Cuentas!$A:$A,"")&"" -> SSP Group | R4: =_xlfn.XLOOKUP(tblMovimientos[[#This Row],[Cuenta Bancaria]],Cuentas!$C:$C,Cuentas!$B:$B,"",0,-1)&""
B5: 46143 | C5: =_xlfn.XLOOKUP(tblMovimientos[[#This Row],[Cuenta Bancaria]],Listas!$B:$B,Listas!$A:$A,"") -> YWC Capital | D5: Bank of America - YWC Capital - 0282-USD | E5: =_xlfn.XLOOKUP(tblMovimientos[[#This Row],[Cuenta Bancaria]],Listas!$B:$B,Listas!$C:$C,"") -> Bank of America | F5: Egreso | G5: Eg.Gastos Bancarios | H5: =IFERROR(_xlfn.XLOOKUP(G5,Listas!E:E,Listas!F:F,""),"") -> Operativo | I5: =IFERROR(_xlfn.XLOOKUP(G5,Listas!E:E,Listas!G:G,""),"") -> Externo | J5: 29.95 | K5: =IF(F5="Ingreso",J5,-J5) -> -29.95 | L5: 2026-05 | M5: =SUMIFS('Saldos Iniciales'!$D:$D,'Saldos Iniciales'!$A:$A,C5,'Saldos Iniciales'!$B:$B,D5)+SUMIFS($K$1:$K$1324,$C$1:$C$1324,C5,$D$1:$D$1324,D5,$B$1:$B$1324,"<="&B5) -> 2267.72 | N5: =IF(tblMovimientos[[#This Row],[Tipo de Movimiento]]="Ingreso",tblMovimientos[[#This Row],[Monto (S/)]],"0") -> 0 | O5: =IF(tblMovimientos[[#This Row],[Tipo de Movimiento]]="Egreso",tblMovimientos[[#This Row],[Monto (S/)]],"0") -> 29.95 | P5: =IF(tblMovimientos[[#This Row],[Tipo de Movimiento]]="Ingreso",tblMovimientos[[#This Row],[Ingreso]],-tblMovimientos[[#This Row],[Egreso]]) -> -29.95 | Q5: =_xlfn.XLOOKUP(tblMovimientos[[#This Row],[Cuenta Bancaria]],Cuentas!$C:$C,Cuentas!$A:$A,"")&"" -> SSP Group | R5: =_xlfn.XLOOKUP(tblMovimientos[[#This Row],[Cuenta Bancaria]],Cuentas!$C:$C,Cuentas!$B:$B,"",0,-1)&""
B6: 46143 | C6: =_xlfn.XLOOKUP(tblMovimientos[[#This Row],[Cuenta Bancaria]],Listas!$B:$B,Listas!$A:$A,"") -> Arbor Capital Properties | D6: Bank of America - Arbor Capital Properties - 3262-USD | E6: =_xlfn.XLOOKUP(tblMovimientos[[#This Row],[Cuenta Bancaria]],Listas!$B:$B,Listas!$C:$C,"") -> Bank of America | F6: Egreso | G6: Eg.Gastos Bancarios | H6: =IFERROR(_xlfn.XLOOKUP(G6,Listas!E:E,Listas!F:F,""),"") -> Operativo | I6: =IFERROR(_xlfn.XLOOKUP(G6,Listas!E:E,Listas!G:G,""),"") -> Externo | J6: 16 | K6: =IF(F6="Ingreso",J6,-J6) -> -16 | L6: 2026-05 | M6: =SUMIFS('Saldos Iniciales'!$D:$D,'Saldos Iniciales'!$A:$A,C6,'Saldos Iniciales'!$B:$B,D6)+SUMIFS($K$1:$K$1324,$C$1:$C$1324,C6,$D$1:$D$1324,D6,$B$1:$B$1324,"<="&B6) -> 1444.08 | N6: =IF(tblMovimientos[[#This Row],[Tipo de Movimiento]]="Ingreso",tblMovimientos[[#This Row],[Monto (S/)]],"0") -> 0 | O6: =IF(tblMovimientos[[#This Row],[Tipo de Movimiento]]="Egreso",tblMovimientos[[#This Row],[Monto (S/)]],"0") -> 16 | P6: =IF(tblMovimientos[[#This Row],[Tipo de Movimiento]]="Ingreso",tblMovimientos[[#This Row],[Ingreso]],-tblMovimientos[[#This Row],[Egreso]]) -> -16 | Q6: =_xlfn.XLOOKUP(tblMovimientos[[#This Row],[Cuenta Bancaria]],Cuentas!$C:$C,Cuentas!$A:$A,"")&"" -> SSP Group | R6: =_xlfn.XLOOKUP(tblMovimientos[[#This Row],[Cuenta Bancaria]],Cuentas!$C:$C,Cuentas!$B:$B,"",0,-1)&""
B7: 46143 | C7: =_xlfn.XLOOKUP(tblMovimientos[[#This Row],[Cuenta Bancaria]],Listas!$B:$B,Listas!$A:$A,"") -> 2515 Overbrook | D7: Bank of America - 2515 Overbrook - 4648-USD | E7: =_xlfn.XLOOKUP(tblMovimientos[[#This Row],[Cuenta Bancaria]],Listas!$B:$B,Listas!$C:$C,"") -> Bank of America | F7: Ingreso | G7: Ing.Cobro de Renta (Real State) | H7: =IFERROR(_xlfn.XLOOKUP(G7,Listas!E:E,Listas!F:F,""),"") -> Operativo | I7: =IFERROR(_xlfn.XLOOKUP(G7,Listas!E:E,Listas!G:G,""),"") -> Externo | J7: 5250 | K7: =IF(F7="Ingreso",J7,-J7) -> 5250 | L7: 2026-05 | M7: =SUMIFS('Saldos Iniciales'!$D:$D,'Saldos Iniciales'!$A:$A,C7,'Saldos Iniciales'!$B:$B,D7)+SUMIFS($K$1:$K$1324,$C$1:$C$1324,C7,$D$1:$D$1324,D7,$B$1:$B$1324,"<="&B7) -> 22922.18 | N7: =IF(tblMovimientos[[#This Row],[Tipo de Movimiento]]="Ingreso",tblMovimientos[[#This Row],[Monto (S/)]],"0") -> 5250 | O7: =IF(tblMovimientos[[#This Row],[Tipo de Movimiento]]="Egreso",tblMovimientos[[#This Row],[Monto (S/)]],"0") -> 0 | P7: =IF(tblMovimientos[[#This Row],[Tipo de Movimiento]]="Ingreso",tblMovimientos[[#This Row],[Ingreso]],-tblMovimientos[[#This Row],[Egreso]]) -> 5250 | Q7: =_xlfn.XLOOKUP(tblMovimientos[[#This Row],[Cuenta Bancaria]],Cuentas!$C:$C,Cuentas!$A:$A,"")&"" -> SSP Group | R7: =_xlfn.XLOOKUP(tblMovimientos[[#This Row],[Cuenta Bancaria]],Cuentas!$C:$C,Cuentas!$B:$B,"",0,-1)&""
B8: 46143 | C8: =_xlfn.XLOOKUP(tblMovimientos[[#This Row],[Cuenta Bancaria]],Listas!$B:$B,Listas!$A:$A,"") -> 2515 Overbrook | D8: Bank of America - 2515 Overbrook - 4648-USD | E8: =_xlfn.XLOOKUP(tblMovimientos[[#This Row],[Cuenta Bancaria]],Listas!$B:$B,Listas!$C:$C,"") -> Bank of America | F8: Egreso | G8: Eg.Deuda Terceros (Intereses+Capital) | H8: =IFERROR(_xlfn.XLOOKUP(G8,Listas!E:E,Listas!F:F,""),"") -> Financiamiento | I8: =IFERROR(_xlfn.XLOOKUP(G8,Listas!E:E,Listas!G:G,""),"") -> Externo | J8: 8578.33 | K8: =IF(F8="Ingreso",J8,-J8) -> -8578.33 | L8: 2026-05 | M8: =SUMIFS('Saldos Iniciales'!$D:$D,'Saldos Iniciales'!$A:$A,C8,'Saldos Iniciales'!$B:$B,D8)+SUMIFS($K$1:$K$1324,$C$1:$C$1324,C8,$D$1:$D$1324,D8,$B$1:$B$1324,"<="&B8) -> 22922.18 | N8: =IF(tblMovimientos[[#This Row],[Tipo de Movimiento]]="Ingreso",tblMovimientos[[#This Row],[Monto (S/)]],"0") -> 0 | O8: =IF(tblMovimientos[[#This Row],[Tipo de Movimiento]]="Egreso",tblMovimientos[[#This Row],[Monto (S/)]],"0") -> 8578.33 | P8: =IF(tblMovimientos[[#This Row],[Tipo de Movimiento]]="Ingreso",tblMovimientos[[#This Row],[Ingreso]],-tblMovimientos[[#This Row],[Egreso]]) -> -8578.33 | Q8: =_xlfn.XLOOKUP(tblMovimientos[[#This Row],[Cuenta Bancaria]],Cuentas!$C:$C,Cuentas!$A:$A,"")&"" -> SSP Group | R8: =_xlfn.XLOOKUP(tblMovimientos[[#This Row],[Cuenta Bancaria]],Cuentas!$C:$C,Cuentas!$B:$B,"",0,-1)&""
B9: 46143 | C9: =_xlfn.XLOOKUP(tblMovimientos[[#This Row],[Cuenta Bancaria]],Listas!$B:$B,Listas!$A:$A,"") -> 2515 Overbrook | D9: Bank of America - 2515 Overbrook - 4648-USD | E9: =_xlfn.XLOOKUP(tblMovimientos[[#This Row],[Cuenta Bancaria]],Listas!$B:$B,Listas!$C:$C,"") -> Bank of America | F9: Egreso | G9: Eg.Gastos Bancarios | H9: =IFERROR(_xlfn.XLOOKUP(G9,Listas!E:E,Listas!F:F,""),"") -> Operativo | I9: =IFERROR(_xlfn.XLOOKUP(G9,Listas!E:E,Listas!G:G,""),"") -> Externo | J9: 16 | K9: =IF(F9="Ingreso",J9,-J9) -> -16 | L9: 2026-05 | M9: =SUMIFS('Saldos Iniciales'!$D:$D,'Saldos Iniciales'!$A:$A,C9,'Saldos Iniciales'!$B:$B,D9)+SUMIFS($K$1:$K$1324,$C$1:$C$1324,C9,$D$1:$D$1324,D9,$B$1:$B$1324,"<="&B9) -> 22922.18 | N9: =IF(tblMovimientos[[#This Row],[Tipo de Movimiento]]="Ingreso",tblMovimientos[[#This Row],[Monto (S/)]],"0") -> 0 | O9: =IF(tblMovimientos[[#This Row],[Tipo de Movimiento]]="Egreso",tblMovimientos[[#This Row],[Monto (S/)]],"0") -> 16 | P9: =IF(tblMovimientos[[#This Row],[Tipo de Movimiento]]="Ingreso",tblMovimientos[[#This Row],[Ingreso]],-tblMovimientos[[#This Row],[Egreso]]) -> -16 | Q9: =_xlfn.XLOOKUP(tblMovimientos[[#This Row],[Cuenta Bancaria]],Cuentas!$C:$C,Cuentas!$A:$A,"")&"" -> SSP Group | R9: =_xlfn.XLOOKUP(tblMovimientos[[#This Row],[Cuenta Bancaria]],Cuentas!$C:$C,Cuentas!$B:$B,"",0,-1)&""
B10: 46143 | C10: =_xlfn.XLOOKUP(tblMovimientos[[#This Row],[Cuenta Bancaria]],Listas!$B:$B,Listas!$A:$A,"") -> 2515 Overbrook | D10: Bank of America - 2515 Overbrook - 9923-USD | E10: =_xlfn.XLOOKUP(tblMovimientos[[#This Row],[Cuenta Bancaria]],Listas!$B:$B,Listas!$C:$C,"") -> Bank of America | F10: Egreso | G10: Eg.Gastos Bancarios | H10: =IFERROR(_xlfn.XLOOKUP(G10,Listas!E:E,Listas!F:F,""),"") -> Operativo | I10: =IFERROR(_xlfn.XLOOKUP(G10,Listas!E:E,Listas!G:G,""),"") -> Externo | J10: 10 | K10: =IF(F10="Ingreso",J10,-J10) -> -10 | L10: 2026-05 | M10: =SUMIFS('Saldos Iniciales'!$D:$D,'Saldos Iniciales'!$A:$A,C10,'Saldos Iniciales'!$B:$B,D10)+SUMIFS($K$1:$K$1324,$C$1:$C$1324,C10,$D$1:$D$1324,D10,$B$1:$B$1324,"<="&B10) -> 340.42 | N10: =IF(tblMovimientos[[#This Row],[Tipo de Movimiento]]="Ingreso",tblMovimientos[[#This Row],[Monto (S/)]],"0") -> 0 | O10: =IF(tblMovimientos[[#This Row],[Tipo de Movimiento]]="Egreso",tblMovimientos[[#This Row],[Monto (S/)]],"0") -> 10 | P10: =IF(tblMovimientos[[#This Row],[Tipo de Movimiento]]="Ingreso",tblMovimientos[[#This Row],[Ingreso]],-tblMovimientos[[#This Row],[Egreso]]) -> -10 | Q10: =_xlfn.XLOOKUP(tblMovimientos[[#This Row],[Cuenta Bancaria]],Cuentas!$C:$C,Cuentas!$A:$A,"")&"" -> SSP Group | R10: =_xlfn.XLOOKUP(tblMovimientos[[#This Row],[Cuenta Bancaria]],Cuentas!$C:$C,Cuentas!$B:$B,"",0,-1)&""
B11: 46143 | C11: =_xlfn.XLOOKUP(tblMovimientos[[#This Row],[Cuenta Bancaria]],Listas!$B:$B,Listas!$A:$A,"") -> 112 Florida Ave | D11: Bank of America - 112 Florida Ave - 3259-USD | E11: =_xlfn.XLOOKUP(tblMovimientos[[#This Row],[Cuenta Bancaria]],Listas!$B:$B,Listas!$C:$C,"") -> Bank of America | F11: Ingreso | G11: Ing.Cobro de Renta (Real State) | H11: =IFERROR(_xlfn.XLOOKUP(G11,Listas!E:E,Listas!F:F,""),"") -> Operativo | I11: =IFERROR(_xlfn.XLOOKUP(G11,Listas!E:E,Listas!G:G,""),"") -> Externo | J11: 6750 | K11: =IF(F11="Ingreso",J11,-J11) -> 6750 | L11: 2026-05 | M11: =SUMIFS('Saldos Iniciales'!$D:$D,'Saldos Iniciales'!$A:$A,C11,'Saldos Iniciales'!$B:$B,D11)+SUMIFS($K$1:$K$1324,$C$1:$C$1324,C11,$D$1:$D$1324,D11,$B$1:$B$1324,"<="&B11) -> 6853.91 | N11: =IF(tblMovimientos[[#This Row],[Tipo de Movimiento]]="Ingreso",tblMovimientos[[#This Row],[Monto (S/)]],"0") -> 6750 | O11: =IF(tblMovimientos[[#This Row],[Tipo de Movimiento]]="Egreso",tblMovimientos[[#This Row],[Monto (S/)]],"0") -> 0 | P11: =IF(tblMovimientos[[#This Row],[Tipo de Movimiento]]="Ingreso",tblMovimientos[[#This Row],[Ingreso]],-tblMovimientos[[#This Row],[Egreso]]) -> 6750 | Q11: =_xlfn.XLOOKUP(tblMovimientos[[#This Row],[Cuenta Bancaria]],Cuentas!$C:$C,Cuentas!$A:$A,"")&"" -> SSP Group | R11: =_xlfn.XLOOKUP(tblMovimientos[[#This Row],[Cuenta Bancaria]],Cuentas!$C:$C,Cuentas!$B:$B,"",0,-1)&""
B12: 46143 | C12: =_xlfn.XLOOKUP(tblMovimientos[[#This Row],[Cuenta Bancaria]],Listas!$B:$B,Listas!$A:$A,"") -> 112 Florida Ave | D12: Bank of America - 112 Florida Ave - 3259-USD | E12: =_xlfn.XLOOKUP(tblMovimientos[[#This Row],[Cuenta Bancaria]],Listas!$B:$B,Listas!$C:$C,"") -> Bank of America | F12: Egreso | G12: Eg.Deuda Terceros (Intereses+Capital) | H12: =IFERROR(_xlfn.XLOOKUP(G12,Listas!E:E,Listas!F:F,""),"") -> Financiamiento | I12: =IFERROR(_xlfn.XLOOKUP(G12,Listas!E:E,Listas!G:G,""),"") -> Externo | J12: 9798.63 | K12: =IF(F12="Ingreso",J12,-J12) -> -9798.63 | L12: 2026-05 | M12: =SUMIFS('Saldos Iniciales'!$D:$D,'Saldos Iniciales'!$A:$A,C12,'Saldos Iniciales'!$B:$B,D12)+SUMIFS($K$1:$K$1324,$C$1:$C$1324,C12,$D$1:$D$1324,D12,$B$1:$B$1324,"<="&B12) -> 6853.91 | N12: =IF(tblMovimientos[[#This Row],[Tipo de Movimiento]]="Ingreso",tblMovimientos[[#This Row],[Monto (S/)]],"0") -> 0 | O12: =IF(tblMovimientos[[#This Row],[Tipo de Movimiento]]="Egreso",tblMovimientos[[#This Row],[Monto (S/)]],"0") -> 9798.63 | P12: =IF(tblMovimientos[[#This Row],[Tipo de Movimiento]]="Ingreso",tblMovimientos[[#This Row],[Ingreso]],-tblMovimientos[[#This Row],[Egreso]]) -> -9798.63 | Q12: =_xlfn.XLOOKUP(tblMovimientos[[#This Row],[Cuenta Bancaria]],Cuentas!$C:$C,Cuentas!$A:$A,"")&"" -> SSP Group | R12: =_xlfn.XLOOKUP(tblMovimientos[[#This Row],[Cuenta Bancaria]],Cuentas!$C:$C,Cuentas!$B:$B,"",0,-1)&""
B13: 46143 | C13: =_xlfn.XLOOKUP(tblMovimientos[[#This Row],[Cuenta Bancaria]],Listas!$B:$B,Listas!$A:$A,"") -> 3628 Thomas Ave | D13: Bank of America - 3628 Thomas Ave - 4406-USD | E13: =_xlfn.XLOOKUP(tblMovimientos[[#This Row],[Cuenta Bancaria]],Listas!$B:$B,Listas!$C:$C,"") -> Bank of America | F13: Ingreso | G13: Ing.Cobro de Renta (Real State) | H13: =IFERROR(_xlfn.XLOOKUP(G13,Listas!E:E,Listas!F:F,""),"") -> Operativo | I13: =IFERROR(_xlfn.XLOOKUP(G13,Listas!E:E,Listas!G:G,""),"") -> Externo | J13: 5050 | K13: =IF(F13="Ingreso",J13,-J13) -> 5050 | L13: 2026-05 | M13: =SUMIFS('Saldos Iniciales'!$D:$D,'Saldos Iniciales'!$A:$A,C13,'Saldos Iniciales'!$B:$B,D13)+SUMIFS($K$1:$K$1324,$C$1:$C$1324,C13,$D$1:$D$1324,D13,$B$1:$B$1324,"<="&B13) -> 21338.39 | N13: =IF(tblMovimientos[[#This Row],[Tipo de Movimiento]]="Ingreso",tblMovimientos[[#This Row],[Monto (S/)]],"0") -> 5050 | O13: =IF(tblMovimientos[[#This Row],[Tipo de Movimiento]]="Egreso",tblMovimientos[[#This Row],[Monto (S/)]],"0") -> 0 | P13: =IF(tblMovimientos[[#This Row],[Tipo de Movimiento]]="Ingreso",tblMovimientos[[#This Row],[Ingreso]],-tblMovimientos[[#This Row],[Egreso]]) -> 5050 | Q13: =_xlfn.XLOOKUP(tblMovimientos[[#This Row],[Cuenta Bancaria]],Cuentas!$C:$C,Cuentas!$A:$A,"")&"" -> SSP Group | R13: =_xlfn.XLOOKUP(tblMovimientos[[#This Row],[Cuenta Bancaria]],Cuentas!$C:$C,Cuentas!$B:$B,"",0,-1)&""
B14: 46143 | C14: =_xlfn.XLOOKUP(tblMovimientos[[#This Row],[Cuenta Bancaria]],Listas!$B:$B,Listas!$A:$A,"") -> 3628 Thomas Ave | D14: Bank of America - 3628 Thomas Ave - 4406-USD | E14: =_xlfn.XLOOKUP(tblMovimientos[[#This Row],[Cuenta Bancaria]],Listas!$B:$B,Listas!$C:$C,"") -> Bank of America | F14: Egreso | G14: Eg.Deuda Terceros (Intereses+Capital) | H14: =IFERROR(_xlfn.XLOOKUP(G14,Listas!E:E,Listas!F:F,""),"") -> Financiamiento | I14: =IFERROR(_xlfn.XLOOKUP(G14,Listas!E:E,Listas!G:G,""),"") -> Externo | J14: 8773.04 | K14: =IF(F14="Ingreso",J14,-J14) -> -8773.04 | L14: 2026-05 | M14: =SUMIFS('Saldos Iniciales'!$D:$D,'Saldos Iniciales'!$A:$A,C14,'Saldos Iniciales'!$B:$B,D14)+SUMIFS($K$1:$K$1324,$C$1:$C$1324,C14,$D$1:$D$1324,D14,$B$1:$B$1324,"<="&B14) -> 21338.39 | N14: =IF(tblMovimientos[[#This Row],[Tipo de Movimiento]]="Ingreso",tblMovimientos[[#This Row],[Monto (S/)]],"0") -> 0 | O14: =IF(tblMovimientos[[#This Row],[Tipo de Movimiento]]="Egreso",tblMovimientos[[#This Row],[Monto (S/)]],"0") -> 8773.04 | P14: =IF(tblMovimientos[[#This Row],[Tipo de Movimiento]]="Ingreso",tblMovimientos[[#This Row],[Ingreso]],-tblMovimientos[[#This Row],[Egreso]]) -> -8773.04 | Q14: =_xlfn.XLOOKUP(tblMovimientos[[#This Row],[Cuenta Bancaria]],Cuentas!$C:$C,Cuentas!$A:$A,"")&"" -> SSP Group | R14: =_xlfn.XLOOKUP(tblMovimientos[[#This Row],[Cuenta Bancaria]],Cuentas!$C:$C,Cuentas!$B:$B,"",0,-1)&""
B15: 46143 | C15: =_xlfn.XLOOKUP(tblMovimientos[[#This Row],[Cuenta Bancaria]],Listas!$B:$B,Listas!$A:$A,"") -> M1B | D15: Amerant Bank - M1B - 0906-USD | E15: =_xlfn.XLOOKUP(tblMovimientos[[#This Row],[Cuenta Bancaria]],Listas!$B:$B,Listas!$C:$C,"") -> Amerant Bank | F15: Ingreso | G15: Ing.Intereses Recibidos de Unidad de Negocio | H15: =IFERROR(_xlfn.XLOOKUP(G15,Listas!E:E,Listas!F:F,""),"") -> Operativo | I15: =IFERROR(_xlfn.XLOOKUP(G15,Listas!E:E,Listas!G:G,""),"") -> Externo | J15: 6748.49 | K15: =IF(F15="Ingreso",J15,-J15) -> 6748.49 | L15: 2026-05 | M15: =SUMIFS('Saldos Iniciales'!$D:$D,'Saldos Iniciales'!$A:$A,C15,'Saldos Iniciales'!$B:$B,D15)+SUMIFS($K$1:$K$1324,$C$1:$C$1324,C15,$D$1:$D$1324,D15,$B$1:$B$1324,"<="&B15) -> 46288.03 | N15: =IF(tblMovimientos[[#This Row],[Tipo de Movimiento]]="Ingreso",tblMovimientos[[#This Row],[Monto (S/)]],"0") -> 6748.49 | O15: =IF(tblMovimientos[[#This Row],[Tipo de Movimiento]]="Egreso",tblMovimientos[[#This Row],[Monto (S/)]],"0") -> 0 | P15: =IF(tblMovimientos[[#This Row],[Tipo de Movimiento]]="Ingreso",tblMovimientos[[#This Row],[Ingreso]],-tblMovimientos[[#This Row],[Egreso]]) -> 6748.49 | Q15: =_xlfn.XLOOKUP(tblMovimientos[[#This Row],[Cuenta Bancaria]],Cuentas!$C:$C,Cuentas!$A:$A,"")&"" -> SSP Group | R15: =_xlfn.XLOOKUP(tblMovimientos[[#This Row],[Cuenta Bancaria]],Cuentas!$C:$C,Cuentas!$B:$B,"",0,-1)&""
... B238: 46174 | C238: =_xlfn.XLOOKUP(tblMovimientos[[#This Row],[Cuenta Bancaria]],Listas!$B:$B,Listas!$A:$A,"") -> Durand | D238: Amerant Bank - Durand - 0106-USD | E238: =_xlfn.XLOOKUP(tblMovimientos[[#This Row],[Cuenta Bancaria]],Listas!$B:$B,Listas!$C:$C,"") -> Amerant Bank | F238: Egreso | G238: Eg.Gastos Bancarios | H238: =IFERROR(_xlfn.XLOOKUP(G238,Listas!E:E,Listas!F:F,""),"") -> Operativo | I238: =IFERROR(_xlfn.XLOOKUP(G238,Listas!E:E,Listas!G:G,""),"") -> Externo | J238: 0 | K238: =IF(F238="Ingreso",J238,-J238) -> 0 | L238: 2026-06 | M238: =SUMIFS('Saldos Iniciales'!$D:$D,'Saldos Iniciales'!$A:$A,C238,'Saldos Iniciales'!$B:$B,D238)+SUMIFS($K$1:$K$1324,$C$1:$C$1324,C238,$D$1:$D$1324,D238,$B$1:$B$1324,"<="&B238) -> 1669.89 | N238: =IF(tblMovimientos[[#This Row],[Tipo de Movimiento]]="Ingreso",tblMovimientos[[#This Row],[Monto (S/)]],"0") -> 0 | O238: =IF(tblMovimientos[[#This Row],[Tipo de Movimiento]]="Egreso",tblMovimientos[[#This Row],[Monto (S/)]],"0") -> 0 | P238: =IF(tblMovimientos[[#This Row],[Tipo de Movimiento]]="Ingreso",tblMovimientos[[#This Row],[Ingreso]],-tblMovimientos[[#This Row],[Egreso]]) -> 0 | Q238: =_xlfn.XLOOKUP(tblMovimientos[[#This Row],[Cuenta Bancaria]],Cuentas!$C:$C,Cuentas!$A:$A,"")&"" -> SSP Group | R238: =_xlfn.XLOOKUP(tblMovimientos[[#This Row],[Cuenta Bancaria]],Cuentas!$C:$C,Cuentas!$B:$B,"",0,-1)&""
B239: 46174 | C239: =_xlfn.XLOOKUP(tblMovimientos[[#This Row],[Cuenta Bancaria]],Listas!$B:$B,Listas!$A:$A,"") -> Green Stone Trust | D239: Bank of America - Green Stone Trust - 3632-USD | E239: =_xlfn.XLOOKUP(tblMovimientos[[#This Row],[Cuenta Bancaria]],Listas!$B:$B,Listas!$C:$C,"") -> Bank of America | F239: Egreso | G239: Eg.Gastos Bancarios | H239: =IFERROR(_xlfn.XLOOKUP(G239,Listas!E:E,Listas!F:F,""),"") -> Operativo | I239: =IFERROR(_xlfn.XLOOKUP(G239,Listas!E:E,Listas!G:G,""),"") -> Externo | K239: =IF(F239="Ingreso",J239,-J239) -> 0 | L239: 2026-06 | M239: =SUMIFS('Saldos Iniciales'!$D:$D,'Saldos Iniciales'!$A:$A,C239,'Saldos Iniciales'!$B:$B,D239)+SUMIFS($K$1:$K$1324,$C$1:$C$1324,C239,$D$1:$D$1324,D239,$B$1:$B$1324,"<="&B239) -> 1968.99 | N239: =IF(tblMovimientos[[#This Row],[Tipo de Movimiento]]="Ingreso",tblMovimientos[[#This Row],[Monto (S/)]],"0") -> 0 | O239: =IF(tblMovimientos[[#This Row],[Tipo de Movimiento]]="Egreso",tblMovimientos[[#This Row],[Monto (S/)]],"0") -> 0 | P239: =IF(tblMovimientos[[#This Row],[Tipo de Movimiento]]="Ingreso",tblMovimientos[[#This Row],[Ingreso]],-tblMovimientos[[#This Row],[Egreso]]) -> 0 | Q239: =_xlfn.XLOOKUP(tblMovimientos[[#This Row],[Cuenta Bancaria]],Cuentas!$C:$C,Cuentas!$A:$A,"")&"" -> SSP Group | R239: =_xlfn.XLOOKUP(tblMovimientos[[#This Row],[Cuenta Bancaria]],Cuentas!$C:$C,Cuentas!$B:$B,"",0,-1)&"" -> Trust
B240: 46174 | C240: =_xlfn.XLOOKUP(tblMovimientos[[#This Row],[Cuenta Bancaria]],Listas!$B:$B,Listas!$A:$A,"") -> Cross Security Trust | D240: Bank of America - Cross Security Trust - 6642-USD | E240: =_xlfn.XLOOKUP(tblMovimientos[[#This Row],[Cuenta Bancaria]],Listas!$B:$B,Listas!$C:$C,"") -> Bank of America | F240: Egreso | G240: Eg.Gastos Operativos (Proveedor) | H240: =IFERROR(_xlfn.XLOOKUP(G240,Listas!E:E,Listas!F:F,""),"") -> Operativo | I240: =IFERROR(_xlfn.XLOOKUP(G240,Listas!E:E,Listas!G:G,""),"") -> Externo | J240: 13270 | K240: =IF(F240="Ingreso",J240,-J240) -> -13270 | L240: 2026-06 | M240: =SUMIFS('Saldos Iniciales'!$D:$D,'Saldos Iniciales'!$A:$A,C240,'Saldos Iniciales'!$B:$B,D240)+SUMIFS($K$1:$K$1324,$C$1:$C$1324,C240,$D$1:$D$1324,D240,$B$1:$B$1324,"<="&B240) -> 20375.37 | N240: =IF(tblMovimientos[[#This Row],[Tipo de Movimiento]]="Ingreso",tblMovimientos[[#This Row],[Monto (S/)]],"0") -> 0 | O240: =IF(tblMovimientos[[#This Row],[Tipo de Movimiento]]="Egreso",tblMovimientos[[#This Row],[Monto (S/)]],"0") -> 13270 | P240: =IF(tblMovimientos[[#This Row],[Tipo de Movimiento]]="Ingreso",tblMovimientos[[#This Row],[Ingreso]],-tblMovimientos[[#This Row],[Egreso]]) -> -13270 | Q240: =_xlfn.XLOOKUP(tblMovimientos[[#This Row],[Cuenta Bancaria]],Cuentas!$C:$C,Cuentas!$A:$A,"")&"" -> SSP Group | R240: =_xlfn.XLOOKUP(tblMovimientos[[#This Row],[Cuenta Bancaria]],Cuentas!$C:$C,Cuentas!$B:$B,"",0,-1)&"" -> Trust
B241: 46174 | C241: =_xlfn.XLOOKUP(tblMovimientos[[#This Row],[Cuenta Bancaria]],Listas!$B:$B,Listas!$A:$A,"") -> Cross Security Trust | D241: Bank of America - Cross Security Trust - 6642-USD | E241: =_xlfn.XLOOKUP(tblMovimientos[[#This Row],[Cuenta Bancaria]],Listas!$B:$B,Listas!$C:$C,"") -> Bank of America | F241: Egreso | G241: Eg.Gastos Operativos (Proveedor) | H241: =IFERROR(_xlfn.XLOOKUP(G241,Listas!E:E,Listas!F:F,""),"") -> Operativo | I241: =IFERROR(_xlfn.XLOOKUP(G241,Listas!E:E,Listas!G:G,""),"") -> Externo | J241: 54445 | K241: =IF(F241="Ingreso",J241,-J241) -> -54445 | L241: 2026-06 | M241: =SUMIFS('Saldos Iniciales'!$D:$D,'Saldos Iniciales'!$A:$A,C241,'Saldos Iniciales'!$B:$B,D241)+SUMIFS($K$1:$K$1324,$C$1:$C$1324,C241,$D$1:$D$1324,D241,$B$1:$B$1324,"<="&B241) -> 20375.37 | N241: =IF(tblMovimientos[[#This Row],[Tipo de Movimiento]]="Ingreso",tblMovimientos[[#This Row],[Monto (S/)]],"0") -> 0 | O241: =IF(tblMovimientos[[#This Row],[Tipo de Movimiento]]="Egreso",tblMovimientos[[#This Row],[Monto (S/)]],"0") -> 54445 | P241: =IF(tblMovimientos[[#This Row],[Tipo de Movimiento]]="Ingreso",tblMovimientos[[#This Row],[Ingreso]],-tblMovimientos[[#This Row],[Egreso]]) -> -54445 | Q241: =_xlfn.XLOOKUP(tblMovimientos[[#This Row],[Cuenta Bancaria]],Cuentas!$C:$C,Cuentas!$A:$A,"")&"" -> SSP Group | R241: =_xlfn.XLOOKUP(tblMovimientos[[#This Row],[Cuenta Bancaria]],Cuentas!$C:$C,Cuentas!$B:$B,"",0,-1)&"" -> Trust
B242: 46175 | C242: =_xlfn.XLOOKUP(tblMovimientos[[#This Row],[Cuenta Bancaria]],Listas!$B:$B,Listas!$A:$A,"") -> 2515 Overbrook | D242: Bank of America - 2515 Overbrook - 4648-USD | E242: =_xlfn.XLOOKUP(tblMovimientos[[#This Row],[Cuenta Bancaria]],Listas!$B:$B,Listas!$C:$C,"") -> Bank of America | F242: Egreso | G242: Eg.Gastos Operativos (Proveedor) | H242: =IFERROR(_xlfn.XLOOKUP(G242,Listas!E:E,Listas!F:F,""),"") -> Operativo | I242: =IFERROR(_xlfn.XLOOKUP(G242,Listas!E:E,Listas!G:G,""),"") -> Externo | J242: 626.3 | K242: =IF(F242="Ingreso",J242,-J242) -> -626.3 | L242: 2026-06 | M242: =SUMIFS('Saldos Iniciales'!$D:$D,'Saldos Iniciales'!$A:$A,C242,'Saldos Iniciales'!$B:$B,D242)+SUMIFS($K$1:$K$1324,$C$1:$C$1324,C242,$D$1:$D$1324,D242,$B$1:$B$1324,"<="&B242) -> 25459.55 | N242: =IF(tblMovimientos[[#This Row],[Tipo de Movimiento]]="Ingreso",tblMovimientos[[#This Row],[Monto (S/)]],"0") -> 0 | O242: =IF(tblMovimientos[[#This Row],[Tipo de Movimiento]]="Egreso",tblMovimientos[[#This Row],[Monto (S/)]],"0") -> 626.3 | P242: =IF(tblMovimientos[[#This Row],[Tipo de Movimiento]]="Ingreso",tblMovimientos[[#This Row],[Ingreso]],-tblMovimientos[[#This Row],[Egreso]]) -> -626.3 | Q242: =_xlfn.XLOOKUP(tblMovimientos[[#This Row],[Cuenta Bancaria]],Cuentas!$C:$C,Cuentas!$A:$A,"")&"" -> SSP Group | R242: =_xlfn.XLOOKUP(tblMovimientos[[#This Row],[Cuenta Bancaria]],Cuentas!$C:$C,Cuentas!$B:$B,"",0,-1)&""
B243: 46175 | C243: =_xlfn.XLOOKUP(tblMovimientos[[#This Row],[Cuenta Bancaria]],Listas!$B:$B,Listas!$A:$A,"") -> Go Blue | D243: Amerant Bank - Go Blue - 8206-USD | E243: =_xlfn.XLOOKUP(tblMovimientos[[#This Row],[Cuenta Bancaria]],Listas!$B:$B,Listas!$C:$C,"") -> Amerant Bank | F243: Egreso | G243: Eg.Gastos Operativos (Proveedor) | H243: =IFERROR(_xlfn.XLOOKUP(G243,Listas!E:E,Listas!F:F,""),"") -> Operativo | I243: =IFERROR(_xlfn.XLOOKUP(G243,Listas!E:E,Listas!G:G,""),"") -> Externo | J243: 3309.58 | K243: =IF(F243="Ingreso",J243,-J243) -> -3309.58 | L243: 2026-06 | M243: =SUMIFS('Saldos Iniciales'!$D:$D,'Saldos Iniciales'!$A:$A,C243,'Saldos Iniciales'!$B:$B,D243)+SUMIFS($K$1:$K$1324,$C$1:$C$1324,C243,$D$1:$D$1324,D243,$B$1:$B$1324,"<="&B243) -> 3514.89 | N243: =IF(tblMovimientos[[#This Row],[Tipo de Movimiento]]="Ingreso",tblMovimientos[[#This Row],[Monto (S/)]],"0") -> 0 | O243: =IF(tblMovimientos[[#This Row],[Tipo de Movimiento]]="Egreso",tblMovimientos[[#This Row],[Monto (S/)]],"0") -> 3309.58 | P243: =IF(tblMovimientos[[#This Row],[Tipo de Movimiento]]="Ingreso",tblMovimientos[[#This Row],[Ingreso]],-tblMovimientos[[#This Row],[Egreso]]) -> -3309.58 | Q243: =_xlfn.XLOOKUP(tblMovimientos[[#This Row],[Cuenta Bancaria]],Cuentas!$C:$C,Cuentas!$A:$A,"")&"" -> SSP Group | R243: =_xlfn.XLOOKUP(tblMovimientos[[#This Row],[Cuenta Bancaria]],Cuentas!$C:$C,Cuentas!$B:$B,"",0,-1)&""
B244: 46176 | C244: =_xlfn.XLOOKUP(tblMovimientos[[#This Row],[Cuenta Bancaria]],Listas!$B:$B,Listas!$A:$A,"") -> SSP Capital | D244: Bank of America - SSP Capital - 2580-USD | E244: =_xlfn.XLOOKUP(tblMovimientos[[#This Row],[Cuenta Bancaria]],Listas!$B:$B,Listas!$C:$C,"") -> Bank of America | F244: Egreso | G244: Eg.Gastos Operativos (Proveedor) | H244: =IFERROR(_xlfn.XLOOKUP(G244,Listas!E:E,Listas!F:F,""),"") -> Operativo | I244: =IFERROR(_xlfn.XLOOKUP(G244,Listas!E:E,Listas!G:G,""),"") -> Externo | J244: 290.01 | K244: =IF(F244="Ingreso",J244,-J244) -> -290.01 | L244: 2026-06 | M244: =SUMIFS('Saldos Iniciales'!$D:$D,'Saldos Iniciales'!$A:$A,C244,'Saldos Iniciales'!$B:$B,D244)+SUMIFS($K$1:$K$1324,$C$1:$C$1324,C244,$D$1:$D$1324,D244,$B$1:$B$1324,"<="&B244) -> 10553.2 | N244: =IF(tblMovimientos[[#This Row],[Tipo de Movimiento]]="Ingreso",tblMovimientos[[#This Row],[Monto (S/)]],"0") -> 0 | O244: =IF(tblMovimientos[[#This Row],[Tipo de Movimiento]]="Egreso",tblMovimientos[[#This Row],[Monto (S/)]],"0") -> 290.01 | P244: =IF(tblMovimientos[[#This Row],[Tipo de Movimiento]]="Ingreso",tblMovimientos[[#This Row],[Ingreso]],-tblMovimientos[[#This Row],[Egreso]]) -> -290.01 | Q244: =_xlfn.XLOOKUP(tblMovimientos[[#This Row],[Cuenta Bancaria]],Cuentas!$C:$C,Cuentas!$A:$A,"")&"" -> SSP Group | R244: =_xlfn.XLOOKUP(tblMovimientos[[#This Row],[Cuenta Bancaria]],Cuentas!$C:$C,Cuentas!$B:$B,"",0,-1)&""
B245: 46176 | C245: =_xlfn.XLOOKUP(tblMovimientos[[#This Row],[Cuenta Bancaria]],Listas!$B:$B,Listas!$A:$A,"") -> Cross Family Trust | D245: Bank of America - Cross Family Trust - 3124-USD | E245: =_xlfn.XLOOKUP(tblMovimientos[[#This Row],[Cuenta Bancaria]],Listas!$B:$B,Listas!$C:$C,"") -> Bank of America | F245: Egreso | G245: Eg.Gastos Operativos (Proveedor) | H245: =IFERROR(_xlfn.XLOOKUP(G245,Listas!E:E,Listas!F:F,""),"") -> Operativo | I245: =IFERROR(_xlfn.XLOOKUP(G245,Listas!E:E,Listas!G:G,""),"") -> Externo | J245: 6000 | K245: =IF(F245="Ingreso",J245,-J245) -> -6000 | L245: 2026-06 | M245: =SUMIFS('Saldos Iniciales'!$D:$D,'Saldos Iniciales'!$A:$A,C245,'Saldos Iniciales'!$B:$B,D245)+SUMIFS($K$1:$K$1324,$C$1:$C$1324,C245,$D$1:$D$1324,D245,$B$1:$B$1324,"<="&B245) -> 51206.89 | N245: =IF(tblMovimientos[[#This Row],[Tipo de Movimiento]]="Ingreso",tblMovimientos[[#This Row],[Monto (S/)]],"0") -> 0 | O245: =IF(tblMovimientos[[#This Row],[Tipo de Movimiento]]="Egreso",tblMovimientos[[#This Row],[Monto (S/)]],"0") -> 6000 | P245: =IF(tblMovimientos[[#This Row],[Tipo de Movimiento]]="Ingreso",tblMovimientos[[#This Row],[Ingreso]],-tblMovimientos[[#This Row],[Egreso]]) -> -6000 | Q245: =_xlfn.XLOOKUP(tblMovimientos[[#This Row],[Cuenta Bancaria]],Cuentas!$C:$C,Cuentas!$A:$A,"")&"" -> SSP Group | R245: =_xlfn.XLOOKUP(tblMovimientos[[#This Row],[Cuenta Bancaria]],Cuentas!$C:$C,Cuentas!$B:$B,"",0,-1)&"" -> Trust
B246: 46177 | C246: =_xlfn.XLOOKUP(tblMovimientos[[#This Row],[Cuenta Bancaria]],Listas!$B:$B,Listas!$A:$A,"") -> Go Blue | D246: Amerant Bank - Go Blue - 8206-USD | E246: =_xlfn.XLOOKUP(tblMovimientos[[#This Row],[Cuenta Bancaria]],Listas!$B:$B,Listas!$C:$C,"") -> Amerant Bank | F246: Egreso | G246: Eg.Gastos Bancarios | H246: =IFERROR(_xlfn.XLOOKUP(G246,Listas!E:E,Listas!F:F,""),"") -> Operativo | I246: =IFERROR(_xlfn.XLOOKUP(G246,Listas!E:E,Listas!G:G,""),"") -> Externo | J246: 15 | K246: =IF(F246="Ingreso",J246,-J246) -> -15 | L246: 2026-06 | M246: =SUMIFS('Saldos Iniciales'!$D:$D,'Saldos Iniciales'!$A:$A,C246,'Saldos Iniciales'!$B:$B,D246)+SUMIFS($K$1:$K$1324,$C$1:$C$1324,C246,$D$1:$D$1324,D246,$B$1:$B$1324,"<="&B246) -> 2422.74 | N246: =IF(tblMovimientos[[#This Row],[Tipo de Movimiento]]="Ingreso",tblMovimientos[[#This Row],[Monto (S/)]],"0") -> 0 | O246: =IF(tblMovimientos[[#This Row],[Tipo de Movimiento]]="Egreso",tblMovimientos[[#This Row],[Monto (S/)]],"0") -> 15 | P246: =IF(tblMovimientos[[#This Row],[Tipo de Movimiento]]="Ingreso",tblMovimientos[[#This Row],[Ingreso]],-tblMovimientos[[#This Row],[Egreso]]) -> -15 | Q246: =_xlfn.XLOOKUP(tblMovimientos[[#This Row],[Cuenta Bancaria]],Cuentas!$C:$C,Cuentas!$A:$A,"")&"" -> SSP Group | R246: =_xlfn.XLOOKUP(tblMovimientos[[#This Row],[Cuenta Bancaria]],Cuentas!$C:$C,Cuentas!$B:$B,"",0,-1)&""
B247: 46177 | C247: =_xlfn.XLOOKUP(tblMovimientos[[#This Row],[Cuenta Bancaria]],Listas!$B:$B,Listas!$A:$A,"") -> Go Blue | D247: Amerant Bank - Go Blue - 8206-USD | E247: =_xlfn.XLOOKUP(tblMovimientos[[#This Row],[Cuenta Bancaria]],Listas!$B:$B,Listas!$C:$C,"") -> Amerant Bank | F247: Egreso | G247: Eg.Gastos Bancarios | H247: =IFERROR(_xlfn.XLOOKUP(G247,Listas!E:E,Listas!F:F,""),"") -> Operativo | I247: =IFERROR(_xlfn.XLOOKUP(G247,Listas!E:E,Listas!G:G,""),"") -> Externo | J247: 15 | K247: =IF(F247="Ingreso",J247,-J247) -> -15 | L247: 2026-06 | M247: =SUMIFS('Saldos Iniciales'!$D:$D,'Saldos Iniciales'!$A:$A,C247,'Saldos Iniciales'!$B:$B,D247)+SUMIFS($K$1:$K$1324,$C$1:$C$1324,C247,$D$1:$D$1324,D247,$B$1:$B$1324,"<="&B247) -> 2422.74 | N247: =IF(tblMovimientos[[#This Row],[Tipo de Movimiento]]="Ingreso",tblMovimientos[[#This Row],[Monto (S/)]],"0") -> 0 | O247: =IF(tblMovimientos[[#This Row],[Tipo de Movimiento]]="Egreso",tblMovimientos[[#This Row],[Monto (S/)]],"0") -> 15 | P247: =IF(tblMovimientos[[#This Row],[Tipo de Movimiento]]="Ingreso",tblMovimientos[[#This Row],[Ingreso]],-tblMovimientos[[#This Row],[Egreso]]) -> -15 | Q247: =_xlfn.XLOOKUP(tblMovimientos[[#This Row],[Cuenta Bancaria]],Cuentas!$C:$C,Cuentas!$A:$A,"")&"" -> SSP Group | R247: =_xlfn.XLOOKUP(tblMovimientos[[#This Row],[Cuenta Bancaria]],Cuentas!$C:$C,Cuentas!$B:$B,"",0,-1)&""
B248: 46177 | C248: =_xlfn.XLOOKUP(tblMovimientos[[#This Row],[Cuenta Bancaria]],Listas!$B:$B,Listas!$A:$A,"") -> Go Blue | D248: Amerant Bank - Go Blue - 8206-USD | E248: =_xlfn.XLOOKUP(tblMovimientos[[#This Row],[Cuenta Bancaria]],Listas!$B:$B,Listas!$C:$C,"") -> Amerant Bank | F248: Egreso | G248: Eg.Gastos Bancarios | H248: =IFERROR(_xlfn.XLOOKUP(G248,Listas!E:E,Listas!F:F,""),"") -> Operativo | I248: =IFERROR(_xlfn.XLOOKUP(G248,Listas!E:E,Listas!G:G,""),"") -> Externo | J248: 15 | K248: =IF(F248="Ingreso",J248,-J248) -> -15 | L248: 2026-06 | M248: =SUMIFS('Saldos Iniciales'!$D:$D,'Saldos Iniciales'!$A:$A,C248,'Saldos Iniciales'!$B:$B,D248)+SUMIFS($K$1:$K$1324,$C$1:$C$1324,C248,$D$1:$D$1324,D248,$B$1:$B$1324,"<="&B248) -> 2422.74 | N248: =IF(tblMovimientos[[#This Row],[Tipo de Movimiento]]="Ingreso",tblMovimientos[[#This Row],[Monto (S/)]],"0") -> 0 | O248: =IF(tblMovimientos[[#This Row],[Tipo de Movimiento]]="Egreso",tblMovimientos[[#This Row],[Monto (S/)]],"0") -> 15 | P248: =IF(tblMovimientos[[#This Row],[Tipo de Movimiento]]="Ingreso",tblMovimientos[[#This Row],[Ingreso]],-tblMovimientos[[#This Row],[Egreso]]) -> -15 | Q248: =_xlfn.XLOOKUP(tblMovimientos[[#This Row],[Cuenta Bancaria]],Cuentas!$C:$C,Cuentas!$A:$A,"")&"" -> SSP Group | R248: =_xlfn.XLOOKUP(tblMovimientos[[#This Row],[Cuenta Bancaria]],Cuentas!$C:$C,Cuentas!$B:$B,"",0,-1)&""
B249: 46177 | C249: =_xlfn.XLOOKUP(tblMovimientos[[#This Row],[Cuenta Bancaria]],Listas!$B:$B,Listas!$A:$A,"") -> SSP Capital | D249: Bank of America - SSP Capital - 2580-USD | E249: =_xlfn.XLOOKUP(tblMovimientos[[#This Row],[Cuenta Bancaria]],Listas!$B:$B,Listas!$C:$C,"") -> Bank of America | F249: Ingreso | G249: Ing.Intereses Recibidos de Unidad de Negocio | H249: =IFERROR(_xlfn.XLOOKUP(G249,Listas!E:E,Listas!F:F,""),"") -> Operativo | I249: =IFERROR(_xlfn.XLOOKUP(G249,Listas!E:E,Listas!G:G,""),"") -> Externo | J249: 15307.88 | K249: =IF(F249="Ingreso",J249,-J249) -> 15307.88 | L249: 2026-06 | M249: =SUMIFS('Saldos Iniciales'!$D:$D,'Saldos Iniciales'!$A:$A,C249,'Saldos Iniciales'!$B:$B,D249)+SUMIFS($K$1:$K$1324,$C$1:$C$1324,C249,$D$1:$D$1324,D249,$B$1:$B$1324,"<="&B249) -> 25322.66 | N249: =IF(tblMovimientos[[#This Row],[Tipo de Movimiento]]="Ingreso",tblMovimientos[[#This Row],[Monto (S/)]],"0") -> 15307.88 | O249: =IF(tblMovimientos[[#This Row],[Tipo de Movimiento]]="Egreso",tblMovimientos[[#This Row],[Monto (S/)]],"0") -> 0 | P249: =IF(tblMovimientos[[#This Row],[Tipo de Movimiento]]="Ingreso",tblMovimientos[[#This Row],[Ingreso]],-tblMovimientos[[#This Row],[Egreso]]) -> 15307.88 | Q249: =_xlfn.XLOOKUP(tblMovimientos[[#This Row],[Cuenta Bancaria]],Cuentas!$C:$C,Cuentas!$A:$A,"")&"" -> SSP Group | R249: =_xlfn.XLOOKUP(tblMovimientos[[#This Row],[Cuenta Bancaria]],Cuentas!$C:$C,Cuentas!$B:$B,"",0,-1)&""
B250: 46177 | C250: =_xlfn.XLOOKUP(tblMovimientos[[#This Row],[Cuenta Bancaria]],Listas!$B:$B,Listas!$A:$A,"") -> SSP Capital | D250: Bank of America - SSP Capital - 2580-USD | E250: =_xlfn.XLOOKUP(tblMovimientos[[#This Row],[Cuenta Bancaria]],Listas!$B:$B,Listas!$C:$C,"") -> Bank of America | F250: Egreso | G250: Eg.Gastos Operativos (Proveedor) | H250: =IFERROR(_xlfn.XLOOKUP(G250,Listas!E:E,Listas!F:F,""),"") -> Operativo | I250: =IFERROR(_xlfn.XLOOKUP(G250,Listas!E:E,Listas!G:G,""),"") -> Externo | J250: 538.42 | K250: =IF(F250="Ingreso",J250,-J250) -> -538.42 | L250: 2026-06 | M250: =SUMIFS('Saldos Iniciales'!$D:$D,'Saldos Iniciales'!$A:$A,C250,'Saldos Iniciales'!$B:$B,D250)+SUMIFS($K$1:$K$1324,$C$1:$C$1324,C250,$D$1:$D$1324,D250,$B$1:$B$1324,"<="&B250) -> 25322.66 | N250: =IF(tblMovimientos[[#This Row],[Tipo de Movimiento]]="Ingreso",tblMovimientos[[#This Row],[Monto (S/)]],"0") -> 0 | O250: =IF(tblMovimientos[[#This Row],[Tipo de Movimiento]]="Egreso",tblMovimientos[[#This Row],[Monto (S/)]],"0") -> 538.42 | P250: =IF(tblMovimientos[[#This Row],[Tipo de Movimiento]]="Ingreso",tblMovimientos[[#This Row],[Ingreso]],-tblMovimientos[[#This Row],[Egreso]]) -> -538.42 | Q250: =_xlfn.XLOOKUP(tblMovimientos[[#This Row],[Cuenta Bancaria]],Cuentas!$C:$C,Cuentas!$A:$A,"")&"" -> SSP Group | R250: =_xlfn.XLOOKUP(tblMovimientos[[#This Row],[Cuenta Bancaria]],Cuentas!$C:$C,Cuentas!$B:$B,"",0,-1)&""
B251: 46177 | C251: =_xlfn.XLOOKUP(tblMovimientos[[#This Row],[Cuenta Bancaria]],Listas!$B:$B,Listas!$A:$A,"") -> A&M Imports | D251: Bank of America - A&M Imports - 3797-USD | E251: =_xlfn.XLOOKUP(tblMovimientos[[#This Row],[Cuenta Bancaria]],Listas!$B:$B,Listas!$C:$C,"") -> Bank of America | F251: Egreso | G251: Eg.Prestamos Concedidos a Unidades de negocio | H251: =IFERROR(_xlfn.XLOOKUP(G251,Listas!E:E,Listas!F:F,""),"") -> Operativo | I251: =IFERROR(_xlfn.XLOOKUP(G251,Listas!E:E,Listas!G:G,""),"") -> Externo | J251: 60000 | K251: =IF(F251="Ingreso",J251,-J251) -> -60000 | L251: 2026-06 | M251: =SUMIFS('Saldos Iniciales'!$D:$D,'Saldos Iniciales'!$A:$A,C251,'Saldos Iniciales'!$B:$B,D251)+SUMIFS($K$1:$K$1324,$C$1:$C$1324,C251,$D$1:$D$1324,D251,$B$1:$B$1324,"<="&B251) -> 729545.24 | N251: =IF(tblMovimientos[[#This Row],[Tipo de Movimiento]]="Ingreso",tblMovimientos[[#This Row],[Monto (S/)]],"0") -> 0 | O251: =IF(tblMovimientos[[#This Row],[Tipo de Movimiento]]="Egreso",tblMovimientos[[#This Row],[Monto (S/)]],"0") -> 60000 | P251: =IF(tblMovimientos[[#This Row],[Tipo de Movimiento]]="Ingreso",tblMovimientos[[#This Row],[Ingreso]],-tblMovimientos[[#This Row],[Egreso]]) -> -60000 | Q251: =_xlfn.XLOOKUP(tblMovimientos[[#This Row],[Cuenta Bancaria]],Cuentas!$C:$C,Cuentas!$A:$A,"")&"" -> SSP Group | R251: =_xlfn.XLOOKUP(tblMovimientos[[#This Row],[Cuenta Bancaria]],Cuentas!$C:$C,Cuentas!$B:$B,"",0,-1)&""
... B313: 46185 | C313: =_xlfn.XLOOKUP(tblMovimientos[[#This Row],[Cuenta Bancaria]],Listas!$B:$B,Listas!$A:$A,"") -> SSP Capital | D313: Amerant Bank - SSP Capital - 4706-USD | E313: =_xlfn.XLOOKUP(tblMovimientos[[#This Row],[Cuenta Bancaria]],Listas!$B:$B,Listas!$C:$C,"") -> Amerant Bank | F313: Ingreso | G313: Ing.Deuda Recibida de Terceros | H313: =IFERROR(_xlfn.XLOOKUP(G313,Listas!E:E,Listas!F:F,""),"") -> Financiamiento | I313: =IFERROR(_xlfn.XLOOKUP(G313,Listas!E:E,Listas!G:G,""),"") -> Externo | J313: 2970000 | K313: =IF(F313="Ingreso",J313,-J313) -> 2970000 | L313: 2026-06 | M313: =SUMIFS('Saldos Iniciales'!$D:$D,'Saldos Iniciales'!$A:$A,C313,'Saldos Iniciales'!$B:$B,D313)+SUMIFS($K$1:$K$1324,$C$1:$C$1324,C313,$D$1:$D$1324,D313,$B$1:$B$1324,"<="&B313) -> 2988249.8 | N313: =IF(tblMovimientos[[#This Row],[Tipo de Movimiento]]="Ingreso",tblMovimientos[[#This Row],[Monto (S/)]],"0") -> 2970000 | O313: =IF(tblMovimientos[[#This Row],[Tipo de Movimiento]]="Egreso",tblMovimientos[[#This Row],[Monto (S/)]],"0") -> 0 | P313: =IF(tblMovimientos[[#This Row],[Tipo de Movimiento]]="Ingreso",tblMovimientos[[#This Row],[Ingreso]],-tblMovimientos[[#This Row],[Egreso]]) -> 2970000 | Q313: =_xlfn.XLOOKUP(tblMovimientos[[#This Row],[Cuenta Bancaria]],Cuentas!$C:$C,Cuentas!$A:$A,"")&"" -> SSP Group | R313: =_xlfn.XLOOKUP(tblMovimientos[[#This Row],[Cuenta Bancaria]],Cuentas!$C:$C,Cuentas!$B:$B,"",0,-1)&""
B314: 46185 | C314: =_xlfn.XLOOKUP(tblMovimientos[[#This Row],[Cuenta Bancaria]],Listas!$B:$B,Listas!$A:$A,"") -> Cross Security Trust | D314: Bank of America - Cross Security Trust - 6642-USD | E314: =_xlfn.XLOOKUP(tblMovimientos[[#This Row],[Cuenta Bancaria]],Listas!$B:$B,Listas!$C:$C,"") -> Bank of America | F314: Ingreso | G314: Ing.Interes bancario | J314: 0.62 | K314: =IF(F314="Ingreso",J314,-J314) -> 0.62 | L314: 2026-06 | M314: =SUMIFS('Saldos Iniciales'!$D:$D,'Saldos Iniciales'!$A:$A,C314,'Saldos Iniciales'!$B:$B,D314)+SUMIFS($K$1:$K$1324,$C$1:$C$1324,C314,$D$1:$D$1324,D314,$B$1:$B$1324,"<="&B314) -> 20375.99 | N314: =IF(tblMovimientos[[#This Row],[Tipo de Movimiento]]="Ingreso",tblMovimientos[[#This Row],[Monto (S/)]],"0") -> 0.62 | O314: =IF(tblMovimientos[[#This Row],[Tipo de Movimiento]]="Egreso",tblMovimientos[[#This Row],[Monto (S/)]],"0") -> 0 | P314: =IF(tblMovimientos[[#This Row],[Tipo de Movimiento]]="Ingreso",tblMovimientos[[#This Row],[Ingreso]],-tblMovimientos[[#This Row],[Egreso]]) -> 0.62 | Q314: =_xlfn.XLOOKUP(tblMovimientos[[#This Row],[Cuenta Bancaria]],Cuentas!$C:$C,Cuentas!$A:$A,"")&"" -> SSP Group | R314: =_xlfn.XLOOKUP(tblMovimientos[[#This Row],[Cuenta Bancaria]],Cuentas!$C:$C,Cuentas!$B:$B,"",0,-1)&"" -> Trust
B315: 46188 | C315: =_xlfn.XLOOKUP(tblMovimientos[[#This Row],[Cuenta Bancaria]],Listas!$B:$B,Listas!$A:$A,"") -> Go Blue | D315: Amerant Bank - Go Blue - 8206-USD | E315: =_xlfn.XLOOKUP(tblMovimientos[[#This Row],[Cuenta Bancaria]],Listas!$B:$B,Listas!$C:$C,"") -> Amerant Bank | F315: Egreso | G315: Eg.Gastos Operativos (Proveedor) | H315: =IFERROR(_xlfn.XLOOKUP(G315,Listas!E:E,Listas!F:F,""),"") -> Operativo | I315: =IFERROR(_xlfn.XLOOKUP(G315,Listas!E:E,Listas!G:G,""),"") -> Externo | J315: 50 | K315: =IF(F315="Ingreso",J315,-J315) -> -50 | L315: 2026-06 | M315: =SUMIFS('Saldos Iniciales'!$D:$D,'Saldos Iniciales'!$A:$A,C315,'Saldos Iniciales'!$B:$B,D315)+SUMIFS($K$1:$K$1324,$C$1:$C$1324,C315,$D$1:$D$1324,D315,$B$1:$B$1324,"<="&B315) -> 48724.73 | N315: =IF(tblMovimientos[[#This Row],[Tipo de Movimiento]]="Ingreso",tblMovimientos[[#This Row],[Monto (S/)]],"0") -> 0 | O315: =IF(tblMovimientos[[#This Row],[Tipo de Movimiento]]="Egreso",tblMovimientos[[#This Row],[Monto (S/)]],"0") -> 50 | P315: =IF(tblMovimientos[[#This Row],[Tipo de Movimiento]]="Ingreso",tblMovimientos[[#This Row],[Ingreso]],-tblMovimientos[[#This Row],[Egreso]]) -> -50 | Q315: =_xlfn.XLOOKUP(tblMovimientos[[#This Row],[Cuenta Bancaria]],Cuentas!$C:$C,Cuentas!$A:$A,"")&"" -> SSP Group | R315: =_xlfn.XLOOKUP(tblMovimientos[[#This Row],[Cuenta Bancaria]],Cuentas!$C:$C,Cuentas!$B:$B,"",0,-1)&""
B316: 46188 | C316: =_xlfn.XLOOKUP(tblMovimientos[[#This Row],[Cuenta Bancaria]],Listas!$B:$B,Listas!$A:$A,"") -> CFT Group | D316: Amerant Bank - CFT Group - 1906-USD | E316: =_xlfn.XLOOKUP(tblMovimientos[[#This Row],[Cuenta Bancaria]],Listas!$B:$B,Listas!$C:$C,"") -> Amerant Bank | F316: Ingreso | G316: Ing.Transferencias entre cuentas (Misma entidad legal) | H316: =IFERROR(_xlfn.XLOOKUP(G316,Listas!E:E,Listas!F:F,""),"") -> Operativo | I316: =IFERROR(_xlfn.XLOOKUP(G316,Listas!E:E,Listas!G:G,""),"") -> Interno | J316: 270000 | K316: =IF(F316="Ingreso",J316,-J316) -> 270000 | L316: 2026-06 | M316: =SUMIFS('Saldos Iniciales'!$D:$D,'Saldos Iniciales'!$A:$A,C316,'Saldos Iniciales'!$B:$B,D316)+SUMIFS($K$1:$K$1324,$C$1:$C$1324,C316,$D$1:$D$1324,D316,$B$1:$B$1324,"<="&B316) -> 968878.52 | N316: =IF(tblMovimientos[[#This Row],[Tipo de Movimiento]]="Ingreso",tblMovimientos[[#This Row],[Monto (S/)]],"0") -> 270000 | O316: =IF(tblMovimientos[[#This Row],[Tipo de Movimiento]]="Egreso",tblMovimientos[[#This Row],[Monto (S/)]],"0") -> 0 | P316: =IF(tblMovimientos[[#This Row],[Tipo de Movimiento]]="Ingreso",tblMovimientos[[#This Row],[Ingreso]],-tblMovimientos[[#This Row],[Egreso]]) -> 270000 | Q316: =_xlfn.XLOOKUP(tblMovimientos[[#This Row],[Cuenta Bancaria]],Cuentas!$C:$C,Cuentas!$A:$A,"")&"" -> SSP Group | R316: =_xlfn.XLOOKUP(tblMovimientos[[#This Row],[Cuenta Bancaria]],Cuentas!$C:$C,Cuentas!$B:$B,"",0,-1)&""
B317: 46188 | C317: =_xlfn.XLOOKUP(tblMovimientos[[#This Row],[Cuenta Bancaria]],Listas!$B:$B,Listas!$A:$A,"") -> CFT Group | D317: Amerant Bank - CFT Group - 1906-USD | E317: =_xlfn.XLOOKUP(tblMovimientos[[#This Row],[Cuenta Bancaria]],Listas!$B:$B,Listas!$C:$C,"") -> Amerant Bank | F317: Egreso | G317: Eg.Deuda Terceros (Intereses+Capital) | H317: =IFERROR(_xlfn.XLOOKUP(G317,Listas!E:E,Listas!F:F,""),"") -> Financiamiento | I317: =IFERROR(_xlfn.XLOOKUP(G317,Listas!E:E,Listas!G:G,""),"") -> Externo | J317: 2366.67 | K317: =IF(F317="Ingreso",J317,-J317) -> -2366.67 | L317: 2026-06 | M317: =SUMIFS('Saldos Iniciales'!$D:$D,'Saldos Iniciales'!$A:$A,C317,'Saldos Iniciales'!$B:$B,D317)+SUMIFS($K$1:$K$1324,$C$1:$C$1324,C317,$D$1:$D$1324,D317,$B$1:$B$1324,"<="&B317) -> 968878.52 | N317: =IF(tblMovimientos[[#This Row],[Tipo de Movimiento]]="Ingreso",tblMovimientos[[#This Row],[Monto (S/)]],"0") -> 0 | O317: =IF(tblMovimientos[[#This Row],[Tipo de Movimiento]]="Egreso",tblMovimientos[[#This Row],[Monto (S/)]],"0") -> 2366.67 | P317: =IF(tblMovimientos[[#This Row],[Tipo de Movimiento]]="Ingreso",tblMovimientos[[#This Row],[Ingreso]],-tblMovimientos[[#This Row],[Egreso]]) -> -2366.67 | Q317: =_xlfn.XLOOKUP(tblMovimientos[[#This Row],[Cuenta Bancaria]],Cuentas!$C:$C,Cuentas!$A:$A,"")&"" -> SSP Group | R317: =_xlfn.XLOOKUP(tblMovimientos[[#This Row],[Cuenta Bancaria]],Cuentas!$C:$C,Cuentas!$B:$B,"",0,-1)&""
B318: 46188 | C318: =_xlfn.XLOOKUP(tblMovimientos[[#This Row],[Cuenta Bancaria]],Listas!$B:$B,Listas!$A:$A,"") -> CFT Group | D318: Amerant Bank - CFT Group - 1906-USD | E318: =_xlfn.XLOOKUP(tblMovimientos[[#This Row],[Cuenta Bancaria]],Listas!$B:$B,Listas!$C:$C,"") -> Amerant Bank | F318: Egreso | G318: Eg.Deuda Terceros (Intereses+Capital) | H318: =IFERROR(_xlfn.XLOOKUP(G318,Listas!E:E,Listas!F:F,""),"") -> Financiamiento | I318: =IFERROR(_xlfn.XLOOKUP(G318,Listas!E:E,Listas!G:G,""),"") -> Externo | J318: 3500 | K318: =IF(F318="Ingreso",J318,-J318) -> -3500 | L318: 2026-06 | M318: =SUMIFS('Saldos Iniciales'!$D:$D,'Saldos Iniciales'!$A:$A,C318,'Saldos Iniciales'!$B:$B,D318)+SUMIFS($K$1:$K$1324,$C$1:$C$1324,C318,$D$1:$D$1324,D318,$B$1:$B$1324,"<="&B318) -> 968878.52 | N318: =IF(tblMovimientos[[#This Row],[Tipo de Movimiento]]="Ingreso",tblMovimientos[[#This Row],[Monto (S/)]],"0") -> 0 | O318: =IF(tblMovimientos[[#This Row],[Tipo de Movimiento]]="Egreso",tblMovimientos[[#This Row],[Monto (S/)]],"0") -> 3500 | P318: =IF(tblMovimientos[[#This Row],[Tipo de Movimiento]]="Ingreso",tblMovimientos[[#This Row],[Ingreso]],-tblMovimientos[[#This Row],[Egreso]]) -> -3500 | Q318: =_xlfn.XLOOKUP(tblMovimientos[[#This Row],[Cuenta Bancaria]],Cuentas!$C:$C,Cuentas!$A:$A,"")&"" -> SSP Group | R318: =_xlfn.XLOOKUP(tblMovimientos[[#This Row],[Cuenta Bancaria]],Cuentas!$C:$C,Cuentas!$B:$B,"",0,-1)&""
B319: 46188 | C319: =_xlfn.XLOOKUP(tblMovimientos[[#This Row],[Cuenta Bancaria]],Listas!$B:$B,Listas!$A:$A,"") -> CFT Group | D319: Amerant Bank - CFT Group - 1906-USD | E319: =_xlfn.XLOOKUP(tblMovimientos[[#This Row],[Cuenta Bancaria]],Listas!$B:$B,Listas!$C:$C,"") -> Amerant Bank | F319: Egreso | G319: Eg.Deuda Terceros (Intereses+Capital) | H319: =IFERROR(_xlfn.XLOOKUP(G319,Listas!E:E,Listas!F:F,""),"") -> Financiamiento | I319: =IFERROR(_xlfn.XLOOKUP(G319,Listas!E:E,Listas!G:G,""),"") -> Externo | J319: 10608.89 | K319: =IF(F319="Ingreso",J319,-J319) -> -10608.89 | L319: 2026-06 | M319: =SUMIFS('Saldos Iniciales'!$D:$D,'Saldos Iniciales'!$A:$A,C319,'Saldos Iniciales'!$B:$B,D319)+SUMIFS($K$1:$K$1324,$C$1:$C$1324,C319,$D$1:$D$1324,D319,$B$1:$B$1324,"<="&B319) -> 968878.52 | N319: =IF(tblMovimientos[[#This Row],[Tipo de Movimiento]]="Ingreso",tblMovimientos[[#This Row],[Monto (S/)]],"0") -> 0 | O319: =IF(tblMovimientos[[#This Row],[Tipo de Movimiento]]="Egreso",tblMovimientos[[#This Row],[Monto (S/)]],"0") -> 10608.89 | P319: =IF(tblMovimientos[[#This Row],[Tipo de Movimiento]]="Ingreso",tblMovimientos[[#This Row],[Ingreso]],-tblMovimientos[[#This Row],[Egreso]]) -> -10608.89 | Q319: =_xlfn.XLOOKUP(tblMovimientos[[#This Row],[Cuenta Bancaria]],Cuentas!$C:$C,Cuentas!$A:$A,"")&"" -> SSP Group | R319: =_xlfn.XLOOKUP(tblMovimientos[[#This Row],[Cuenta Bancaria]],Cuentas!$C:$C,Cuentas!$B:$B,"",0,-1)&""
